Workbook

Sheet __DATA__
A1: Tab | B1: Slot | C1: Option | D1: Instruction | E1: Swap Note
A2: Pre-Cleanse | B2: Salmon Method | C2: Baked | D2: BAKED: Preheat oven to 400F. Place salmon on a lightly oiled baking sheet, skin side down. Season with sea salt and black pepper. Bake 12-15 minutes until the fish flakes easily with a fork at the thickest part. Do not overcook - salmon continues cooking from residual heat after removal. Rest 2 minutes before plating. | E2: Most hands-off method - great for multitasking with rice and asparagus.
A3: Pre-Cleanse | B3: Salmon Method | C3: Grilled | D3: GRILLED: Heat grill or grill pan to medium-high. Brush salmon lightly with olive oil, season with sea salt and pepper. Place skin-side up first. Grill 4-5 minutes per side until cooked through with visible grill marks. The salmon is done when it flakes easily at the thickest point. Rest 2 minutes before plating. | E3: Most flavorful through caramelization. A stovetop grill pan works perfectly.
A4: Pre-Cleanse | B4: Salmon Method | C4: Sous Vide | D4: SOUS VIDE: Set immersion circulator to 125F for medium-rare or 130F for medium. Season salmon, seal in a bag, submerge. Cook 45 minutes. When done, optionally finish with a quick 30-second sear in a very hot dry pan for a light crust. Rest 1 minute before plating. | E4: Most precise result. Requires an immersion circulator. Start this method first - it takes longest.
A5: Pre-Cleanse | B5: Asparagus Prep | C5: Steamed | D5: STEAMED: Snap woody ends off asparagus where they naturally break. Steam over 1 inch of boiling purified water for 5-7 minutes until just tender with a slight bite. Do not overcook. Season lightly with sea salt and a squeeze of lemon. | E5: Best nutrient preservation. Best match for the Baked salmon method.
A6: Pre-Cleanse | B6: Asparagus Prep | C6: Roasted | D6: ROASTED: Preheat oven to 400F. Spread asparagus in a single layer on a baking sheet. Drizzle very lightly with olive oil, season with sea salt and pepper. Roast 10-12 minutes until tender with slightly caramelized tips. | E6: Richest flavor through caramelization. Pairs with Baked or Grilled salmon.
A7: Pre-Cleanse | B7: Asparagus Prep | C7: Grilled | D7: GRILLED: Heat grill or grill pan to medium-high. Toss asparagus with a tiny amount of olive oil and season with sea salt and pepper. Grill 3-4 minutes turning once. Should have grill marks and be tender throughout. | E7: Cook alongside grilled salmon at the same time for efficiency.
A8: Morning | B8: Citrus Water | C8: Fresh Lime (half) | D8: Cut a fresh lime in half. Squeeze the juice of one half into a full glass of purified water (about 8 oz). Stir and drink within 5 minutes of your probiotic water. The sour taste is intentional and beneficial - do not add anything to sweeten it. | E8: Lime is slightly less tart than lemon. Same detox benefit.
A9: Morning | B9: Citrus Water | C9: Fresh Lemon (half) | D9: Cut a fresh lemon in half. Squeeze the juice of one half into a full glass of purified water (about 8 oz). Stir and drink within 5 minutes of your probiotic water. Lemon has a slightly more tart profile than lime. Both are equally effective - use whichever you have fresher that day. | E9: Lemon is slightly more tart than lime. Same detox benefit.
A10: Breakfast | B10: Breakfast Recipe | C10: Berry Prune Smoothie Bowl | D10: BERRY PRUNE SMOOTHIE BOWL: Add to blender: 1 cup frozen berries (raspberries, strawberries, or blueberries), 4-5 soaked prunes plus ALL soaking liquid, 1 chopped seasonal fruit (mango, papaya, peach, or pear), and 1/4 cup purified water. Blend on high 30-45 seconds until completely smooth. Should be thick enough to eat with a spoon. Pour into a wide bowl and eat slowly. | E10: Most filling option. Best for days when you need sustained energy. NO BANANAS - they are constipating.
A11: Breakfast | B11: Breakfast Recipe | C11: Tropical Fruit Salad with Prune Sauce | D11: TROPICAL FRUIT SALAD: Chop 1 medium apple (do not peel) and 1 cup of seasonal fruit (mango, papaya, peach, or nectarine) into bite-sized pieces. Add to a bowl. Squeeze fresh lemon or lime juice over immediately. Roughly chop 4-5 soaked prunes and add them with ALL their soaking liquid to the bowl. Stir gently - the liquid becomes a naturally sweet sauce. Eat slowly and chew thoroughly. | E11: No equipment needed. Most beginner-friendly. Best for days 1-3.
A12: Breakfast | B12: Breakfast Recipe | C12: Green Citrus Smoothie | D12: GREEN CITRUS SMOOTHIE: Add to blender in this order: 1/2 cup purified water first, then 1 large handful of kale or spinach (stems removed), then 1 peeled orange or 2 tangerines, then 1 cored apple, then 3-4 soaked prunes plus their liquid. Blend on HIGH for 45-60 seconds until uniformly green with no visible leaf pieces. Drink immediately - green smoothies oxidize quickly. | E12: Most detox-forward. Best when brain fog or headache is present. Palate adjusts by day 3.
... A57: Evening | B57: Evening Tea | C57: Senna Tea - Evening Only - Use Carefully | D57: SENNA TEA - READ CAREFULLY: Senna is a stimulant laxative, significantly stronger than herbal detox tea. RULES: (1) Evening ONLY - never morning or afternoon. (2) NEVER two consecutive nights. (3) Best reserved for day 2 or 3 ONLY if elimination has been notably slow. (4) Not recommended for anyone with digestive sensitivities or on medications without consulting a doctor first. Steep 1 bag for 3 minutes ONLY. Expect results 6-12 hours later. | E57: USE SPARINGLY. Evening only. Never two consecutive nights. Read all cautions above.

Sheet Pre-Cleanse Meal
A1: 7-Day Organic Vegan Detox & Cleanse - Pre-Cleanse Meal
A2: Recipe: Salmon, Asparagus & Black Rice | Time: ~40 minutes | Method: Baked / Grilled / Sous Vide
A4: WHY THIS MEAL
A5: A calm, clean, satisfying meal the evening before Day 1. Salmon provides omega-3s and clean protein. Asparagus is a natural diuretic that begins flushing the system. Black rice digests slowly, keeping you full and stable through your first cleanse morning.
A7: INGREDIENT SLOTS - Use dropdowns in the YOUR SELECTION column to customize your recipe
B8: Ingredient Slot | C8: YOUR SELECTION | D8: Recipe Instructions (updates with your selection) | E8: Swap Note | F8: Alt Option 1 | G8: Alt Option 2
B9: Salmon Method | C9: Baked | D9: =IFERROR(INDEX(__DATA__!$D$2:$D$4,MATCH(C9,__DATA__!$C$2:$C$4,0)),"Select an option from the dropdown above") -> BAKED: Preheat oven to 400F. Place salmon on a lightly oiled baking sheet, skin side down. Season with sea salt and black pepper. Bake 12-15 minutes until the fish flakes easily with a fork at the thickest part. Do not overcook - salmon continues cooking from residual heat after removal. Rest 2 minutes before plating. | E9: =IFERROR(INDEX(__DATA__!$E$2:$E$4,MATCH(C9,__DATA__!$C$2:$C$4,0)),"") -> Most hands-off method - great for multitasking with rice and asparagus. | F9: Grilled | G9: Sous Vide
B10: Asparagus Prep | C10: Steamed | D10: =IFERROR(INDEX(__DATA__!$D$5:$D$7,MATCH(C10,__DATA__!$C$5:$C$7,0)),"Select an option from the dropdown above") -> STEAMED: Snap woody ends off asparagus where they naturally break. Steam over 1 inch of boiling purified water for 5-7 minutes until just tender with a slight bite. Do not overcook. Season lightly with sea salt and a squeeze of lemon. | E10: =IFERROR(INDEX(__DATA__!$E$5:$E$7,MATCH(C10,__DATA__!$C$5:$C$7,0)),"") -> Best nutrient preservation. Best match for the Baked salmon method. | F10: Roasted | G10: Grilled
A12: STEP-BY-STEP INSTRUCTIONS - Follow these steps in order
A13: Steps marked with * reference your dropdown selections above - those cells update automatically when you change your selection.
A14: STEP 1 - Cook Black Rice First
A15: Rinse 1/2 cup black rice. Combine with 1-1/4 cups purified water. Bring to boil, reduce to low, cover and simmer 30-35 minutes until water is absorbed. Remove from heat, let sit covered 5 minutes. A rice cooker on the black rice setting also works.
A16: STEP 2 - Prepare the Salmon
A17: See YOUR SELECTION column - the instructions change based on your chosen method above.
A18: STEP 3 - Cook the Asparagus
A19: See YOUR SELECTION column - the instructions change based on your chosen prep method.
A20: STEP 4 - Plate and Serve
A21: Serve salmon alongside asparagus and a generous scoop of black rice. Keep it simple - this meal is about calm and nourishment, not complexity. Eat slowly and mindfully. Tonight sets the tone for your week. After dinner: soak prunes and almonds for tomorrow.
A23: TIPS AND NOTES
A24: - Soak prunes in 1/2 cup purified water tonight - you need them for breakfast tomorrow morning.
... A27: - Set out your supplements and shaker bottle tonight so your morning routine takes under 5 minutes.

Sheet Morning Routine
A1: 7-Day Organic Vegan Detox & Cleanse - Morning Routine
A2: Recipe: Morning Routine - Every Day Upon Rising | Time: 5-8 minutes | Method: Drinks - Do this before anything else
A4: WHY THIS MEAL
A5: The ignition sequence for each day's cleansing work. Probiotics on an empty stomach reach the gut at highest potency. Citrus water stimulates stomach acid and bile production. The morning fiber drink begins sweeping the intestinal tract before any food enters, maximizing toxin elimination all day.
A7: INGREDIENT SLOTS - Use dropdowns in the YOUR SELECTION column to customize your recipe
B8: Ingredient Slot | C8: YOUR SELECTION | D8: Recipe Instructions (updates with your selection) | E8: Swap Note | F8: Alt Option 1 | G8: Alt Option 2
B9: Citrus Water | C9: Fresh Lime (half) | D9: =IFERROR(INDEX(__DATA__!$D$8:$D$9,MATCH(C9,__DATA__!$C$8:$C$9,0)),"Select an option from the dropdown above") -> Cut a fresh lime in half. Squeeze the juice of one half into a full glass of purified water (about 8 oz). Stir and drink within 5 minutes of your probiotic water. The sour taste is intentional and beneficial - do not add anything to sweeten it. | E9: =IFERROR(INDEX(__DATA__!$E$8:$E$9,MATCH(C9,__DATA__!$C$8:$C$9,0)),"") -> Lime is slightly less tart than lemon. Same detox benefit. | F9: Fresh Lemon (half)
A11: STEP-BY-STEP INSTRUCTIONS - Follow these steps in order
A12: Steps marked with * reference your dropdown selections above - those cells update automatically when you change your selection.
A13: STEP 1 - Step 1 - Probiotics First
A14: Before anything else - before food, before coffee, before your phone - drink a full 8 oz glass of purified water with your probiotics. Follow the dosage on your bottle. Probiotics on a completely empty stomach reach the gut at their highest potency.
A15: STEP 2 - Step 2 - Citrus Water
A16: See YOUR SELECTION column for your chosen citrus. Drink within 5 minutes of your probiotic water. This stimulates stomach acid and bile production for the day ahead.
A17: STEP 3 - Step 3 - Morning Fiber Drink
A18: Add 8 oz room temperature purified water to your shaker bottle. Add 1 Tbsp ground flax seed. Add 1 tsp unsweetened cranberry concentrate. Seal and shake vigorously for 10 seconds. Drink promptly - flax thickens within 1-2 minutes. NOTE: cranberry concentrate is used in the MORNING drink only - omit it from the evening version.
A19: STEP 4 - Exercise Note
A20: If exercising this week: keep it gentle. Your body is redirecting energy toward detoxification. Light walking, yoga, or stretching are ideal. Avoid intense cardio or strength training in the first 3 days. You may feel weaker than usual - this is completely normal and temporary.
A22: TIPS AND NOTES
A23: - Set out supplements, shaker bottle, and probiotic the night before - morning routine should take under 5 minutes.
... A25: - Cranberry concentrate MUST be unsweetened - sweetened cranberry juice is not a substitute.

Sheet Breakfast
A1: 7-Day Organic Vegan Detox & Cleanse - Breakfast
A2: Recipe: Breakfast - Choose One of 3 Recipes | Time: 5-8 minutes + overnight soak | Method: Blended or Raw
A4: WHY THIS MEAL
A5: Fruit-forward breakfast works with your digestive system, which handles fruit enzymes most efficiently in the morning. The soaked prunes and their liquid are non-negotiable - they provide gentle digestive support critical for Days 1-2.
A7: INGREDIENT SLOTS - Use dropdowns in the YOUR SELECTION column to customize your recipe
B8: Ingredient Slot | C8: YOUR SELECTION | D8: Recipe Instructions (updates with your selection) | E8: Swap Note | F8: Alt Option 1 | G8: Alt Option 2
B9: Breakfast Recipe | C9: Berry Prune Smoothie Bowl | D9: =IFERROR(INDEX(__DATA__!$D$10:$D$12,MATCH(C9,__DATA__!$C$10:$C$12,0)),"Select an option from the dropdown above") -> BERRY PRUNE SMOOTHIE BOWL: Add to blender: 1 cup frozen berries (raspberries, strawberries, or blueberries), 4-5 soaked prunes plus ALL soaking liquid, 1 chopped seasonal fruit (mango, papaya, peach, or pear), and 1/4 cup purified water. Blend on high 30-45 seconds until completely smooth. Should be thick enough to eat with a spoon. Pour into a wide bowl and eat slowly. | E9: =IFERROR(INDEX(__DATA__!$E$10:$E$12,MATCH(C9,__DATA__!$C$10:$C$12,0)),"") -> Most filling option. Best for days when you need sustained energy. NO BANANAS - they are constipating. | F9: Tropical Fruit Salad with Prune Sauce | G9: Green Citrus Smoothie
B10: Berry Type | C10: Frozen Raspberries | D10: =IFERROR(INDEX(__DATA__!$D$13:$D$16,MATCH(C10,__DATA__!$C$13:$C$16,0)),"Select an option from the dropdown above") -> Use 1 cup frozen raspberries. Deepest red color, most intensely flavored. Highest fiber of the berry options. | E10: =IFERROR(INDEX(__DATA__!$E$13:$E$16,MATCH(C10,__DATA__!$C$13:$C$16,0)),"") -> Best for days 4-7 when palate has adjusted to less sweet flavors. | F10: Frozen Strawberries | G10: Frozen Blueberries
B11: Green Smoothie Base | C11: Kale | D11: =IFERROR(INDEX(__DATA__!$D$17:$D$20,MATCH(C11,__DATA__!$C$17:$C$20,0)),"Select an option from the dropdown above") -> Remove kale stems completely - fold each leaf in half and pull the stem away. Use leaves only. Wash thoroughly. Most potent detox green. | E11: =IFERROR(INDEX(__DATA__!$E$17:$E$20,MATCH(C11,__DATA__!$C$17:$C$20,0)),"") -> Most potent. Requires complete stem removal for smooth blending. | F11: Spinach | G11: Beet Greens
A13: STEP-BY-STEP INSTRUCTIONS - Follow these steps in order
A14: Steps marked with * reference your dropdown selections above - those cells update automatically when you change your selection.
A15: STEP 1 - Night Before - Soak Prunes
A16: Place 4-5 dried prunes in a glass. Cover with 1/2 cup purified water. Leave overnight on the counter or in the refrigerator. By morning the liquid will be sweet, dark, and slightly syrupy. Both the prunes AND their liquid are used in your breakfast. Do not discard a single drop of the soaking liquid.
A17: STEP 2 - Morning - Prepare Your Chosen Recipe
A18: See YOUR SELECTION column above. Choose your Breakfast Recipe from the dropdown, then follow the instructions that appear. If making the Smoothie Bowl, also select your Berry Type. If making the Green Citrus Smoothie, also select your Green Smoothie Base.
A19: STEP 3 - Eat Slowly
A20: Regardless of which breakfast you choose, eat slowly and chew thoroughly. Digestion begins in the mouth and thorough chewing is especially important during a cleanse when your digestive system is adjusting. Take at least 10 minutes for breakfast.
A22: TIPS AND NOTES
A23: - NO BANANAS at any point during the cleanse - they are constipating and work against the program.
A24: - Not sweet enough? Add one more prune. NEVER add sugar, honey, or any sweetener.
A25: - Blender struggling with frozen fruit? Let berries sit at room temperature for 5 minutes first.
A26: - Green smoothie tasting too bitter? Add one more piece of sweet fruit and blend 10 more seconds.

Sheet Mid-Morning Juice
A1: 7-Day Organic Vegan Detox & Cleanse - Mid-Morning Juice
A2: Recipe: Mid-Morning Juice - Choose One of 3 Recipes | Time: 8 minutes | Method: Fresh Pressed - Juicer Required
A4: WHY THIS MEAL
A5: Fresh juice delivers a concentrated dose of live enzymes, vitamins, and diuretic compounds that bottled juice cannot replicate. Bottled juice is pasteurized, which destroys the live enzymes that make fresh juice therapeutically different. By noon you should have consumed at least half your daily water goal.
A7: INGREDIENT SLOTS - Use dropdowns in the YOUR SELECTION column to customize your recipe
B8: Ingredient Slot | C8: YOUR SELECTION | D8: Recipe Instructions (updates with your selection) | E8: Swap Note | F8: Alt Option 1 | G8: Alt Option 2
B9: Juice Recipe | C9: Apple Carrot Ginger Juice | D9: =IFERROR(INDEX(__DATA__!$D$21:$D$23,MATCH(C9,__DATA__!$C$21:$C$23,0)),"Select an option from the dropdown above") -> APPLE CARROT GINGER JUICE: Wash 3 medium apples and 4 large carrots. Core apples and cut into wedges (do not peel). Scrub carrots and trim tops (do not peel). Peel 1 inch of fresh ginger and peel 1/2 lemon. Juice in this order: carrots first, then apple, then ginger, then lemon last. Stir the finished juice well and drink immediately. Masticating juicer: up to 20 min before oxidation. Centrifugal juicer: drink within 10-15 minutes. | E9: =IFERROR(INDEX(__DATA__!$E$21:$E$23,MATCH(C9,__DATA__!$C$21:$C$23,0)),"") -> Best for days 1-3 when adjusting to juicing. Most approachable flavor. | F9: Green Detox Juice | G9: Citrus Beet Juice
B10: Root Vegetable | C10: Carrot | D10: =IFERROR(INDEX(__DATA__!$D$24:$D$25,MATCH(C10,__DATA__!$C$24:$C$25,0)),"Select an option from the dropdown above") -> Use 4 large carrots (scrubbed, tops trimmed, do not peel). Orange juice color, mildly sweet, most approachable. Excellent for days 1-3. | E10: =IFERROR(INDEX(__DATA__!$E$24:$E$25,MATCH(C10,__DATA__!$C$24:$C$25,0)),"") -> No staining concern. Good intro to root vegetable juicing. | F10: Beet
B11: Juice Herb | C11: Parsley | D11: =IFERROR(INDEX(__DATA__!$D$26:$D$28,MATCH(C11,__DATA__!$C$26:$C$28,0)),"Select an option from the dropdown above") -> Use a large handful of fresh parsley including stems. Wash very thoroughly - parsley carries grit between leaves. Strongest kidney-cleansing herb option. | E11: =IFERROR(INDEX(__DATA__!$E$26:$E$28,MATCH(C11,__DATA__!$C$26:$C$28,0)),"") -> Best kidney cleansing option. Best for days 2-7. | F11: Cilantro | G11: Fresh Mint
A13: STEP-BY-STEP INSTRUCTIONS - Follow these steps in order
A14: Steps marked with * reference your dropdown selections above - those cells update automatically when you change your selection.
A15: STEP 1 - Wash and Prep All Produce
A16: Wash all produce thoroughly. For the Green Detox Juice, wash parsley especially carefully as it carries grit between its leaves. For the Citrus Beet Juice, protect your cutting surface before handling beets - the juice stains permanently.
A17: STEP 2 - Juice in the Correct Order
A18: See YOUR SELECTION column for your chosen recipe instructions. The order in which you feed produce into the juicer matters - follow the recipe order exactly. Denser produce goes first to build juice flow; citrus always goes last to clean remaining juice through.
A19: STEP 3 - Stir, Taste, and Drink
A20: Stir the finished juice - layers settle quickly. Taste before drinking. Adjust with more apple if too strong, more citrus if too flat. Drink immediately for maximum nutritional benefit. Clean your juicer right away while pulp is still wet.
A22: TIPS AND NOTES
A23: - Save your juice pulp - mix it into the evening vegetable broth for extra nutrients.
A24: - Feeling most bloated on days 1-2? Choose the Green Detox Juice - works fastest for reducing water retention.
A25: - New to green juice? Start with 1 celery stalk and 1 extra apple, then build to the full recipe by day 3.
A26: - Masticating juicer extracts more nutrients with less oxidation - strongly recommended over centrifugal.

Sheet Lunch
A1: 7-Day Organic Vegan Detox & Cleanse - Lunch
A2: Recipe: Lunch - Choose One of 3 Salad Recipes | Time: 10-15 minutes | Method: Raw or Steamed over Raw
A4: WHY THIS MEAL
A5: Lunch is your largest meal and primary daily dose of dark leafy greens. Eat as much of the green base as you want - the greens are doing the toxin-binding work central to the whole program. Take Digestive Enzymes with or immediately after this meal.
A7: INGREDIENT SLOTS - Use dropdowns in the YOUR SELECTION column to customize your recipe
B8: Ingredient Slot | C8: YOUR SELECTION | D8: Recipe Instructions (updates with your selection) | E8: Swap Note | F8: Alt Option 1 | G8: Alt Option 2
B9: Salad Recipe | C9: Classic Detox Salad | D9: =IFERROR(INDEX(__DATA__!$D$29:$D$31,MATCH(C9,__DATA__!$C$29:$C$31,0)),"Select an option from the dropdown above") -> CLASSIC DETOX SALAD: Build a large base of 3-4 handfuls mixed lettuce plus 1 handful kale or spinach. Add: grated carrots, sliced red onion, cucumber, sprouts, chopped beets, and a small handful of fresh parsley. DRESSING: 1 Tbsp extra virgin olive oil plus fresh lemon juice or 1.5 tsp raw unfiltered apple cider vinegar. Toss thoroughly. Take Digestive Enzymes as directed. Eat slowly and chew every bite thoroughly - raw vegetables require significant digestion. | E9: =IFERROR(INDEX(__DATA__!$E$29:$E$31,MATCH(C9,__DATA__!$C$29:$C$31,0)),"") -> Best everyday salad for days 1-7. Most meal-prep friendly. | F9: Warm Steamed Veggie Salad | G9: Chopped Beet and Sprout Salad
B10: Dark Leafy Green | C10: Kale | D10: =IFERROR(INDEX(__DATA__!$D$32:$D$35,MATCH(C10,__DATA__!$C$32:$C$35,0)),"Select an option from the dropdown above") -> Remove stems completely, tear into bite-sized pieces. For raw salads, massage with a few drops of lemon juice for 60 seconds to tenderize. Most potent toxin-binding green. | E10: =IFERROR(INDEX(__DATA__!$E$32:$E$35,MATCH(C10,__DATA__!$C$32:$C$35,0)),"") -> Massage it for best results - 60 seconds makes a dramatic difference in texture and bitterness. | F10: Spinach | G10: Collard Ribbons
B11: Salad Dressing | C11: Lemon and Olive Oil | D11: =IFERROR(INDEX(__DATA__!$D$36:$D$38,MATCH(C11,__DATA__!$C$36:$C$38,0)),"Select an option from the dropdown above") -> Drizzle 1 Tbsp extra virgin olive oil evenly over the salad. Squeeze fresh lemon juice over everything. Toss thoroughly. Brightest and most versatile dressing option. | E11: =IFERROR(INDEX(__DATA__!$E$36:$E$38,MATCH(C11,__DATA__!$C$36:$C$38,0)),"") -> Most versatile - pairs with all salad options. | F11: Lime and Olive Oil | G11: Apple Cider Vinegar and Olive Oil
A13: STEP-BY-STEP INSTRUCTIONS - Follow these steps in order
A14: Steps marked with * reference your dropdown selections above - those cells update automatically when you change your selection.
A15: STEP 1 - Build Your Green Base
A16: Choose your salad recipe and dark leafy green using the dropdowns above. See the YOUR SELECTION column for your specific salad recipe instructions. Add 3-4 large handfuls of mixed lettuce plus your selected dark leafy green to a large bowl.
A17: STEP 2 - Add Toppings and Dress
A18: Add your chosen toppings based on the salad recipe instructions. Apply your selected dressing using the instructions in the YOUR SELECTION column. Toss thoroughly so every leaf is lightly coated.
A19: STEP 3 - Take Digestive Enzymes and Eat
A20: Take Digestive Enzymes as directed on the bottle - chew 3-9 tabs with or immediately after this meal. Eat slowly and chew every bite thoroughly. Take 15-20 minutes. Still hungry? Add more lettuce greens - they are unlimited on this cleanse.
A22: TIPS AND NOTES
A23: - The olive oil is NOT optional - fat-soluble vitamins A, D, E, and K from greens cannot be absorbed without dietary fat.
A24: - Eat as much lettuce greens as you like - they are unlimited. Add more greens if still hungry after the salad.
A25: - Broccoli sprouts are the best upgrade for regular sprouts - highest sulforaphane content of any food available.
A26: - This salad travels well - pack in a glass container with dressing in a separate small jar.

Sheet Afternoon Snack
A1: 7-Day Organic Vegan Detox & Cleanse - Afternoon Snack
A2: Recipe: Afternoon Snack - Choose One of 2 Options | Time: 3-10 minutes | Method: Raw or Raw plus Fresh Pressed
A4: WHY THIS MEAL
A5: The 2-4 PM window is the most vulnerable point of any cleanse. Almonds provide the only significant protein and fat outside breakfast - this stabilizes blood sugar and ends cravings at the biochemical level. Drink 16 oz water FIRST, before any food. Cravings are often thirst in disguise.
A7: INGREDIENT SLOTS - Use dropdowns in the YOUR SELECTION column to customize your recipe
B8: Ingredient Slot | C8: YOUR SELECTION | D8: Recipe Instructions (updates with your selection) | E8: Swap Note | F8: Alt Option 1 | G8: Alt Option 2
B9: Snack Option | C9: Celery and Almonds with Herbal Tea | D9: =IFERROR(INDEX(__DATA__!$D$39:$D$40,MATCH(C9,__DATA__!$C$39:$C$40,0)),"Select an option from the dropdown above") -> CELERY AND ALMONDS WITH HERBAL TEA: Drink your full 16 oz of water FIRST before eating anything. Then wash 3-4 celery stalks (include the leaves - they are more nutritious than the stalks). Cut into 3-4 inch pieces. Arrange on a plate alongside your soaked almonds (12-15 almonds). Brew your detox tea: steep 1-2 bags for 3-5 minutes covered. No sweetener. Eat the celery and almonds slowly, alternating between them, while sipping the tea. Take 10-15 minutes for this snack. | E9: =IFERROR(INDEX(__DATA__!$E$39:$E$40,MATCH(C9,__DATA__!$C$39:$C$40,0)),"") -> Best option for days when hunger is intense - most filling. No juicer needed. | F9: Apple Slices with Green Juice
B10: Crunchy Vegetable | C10: Celery Stalks | D10: =IFERROR(INDEX(__DATA__!$D$41:$D$43,MATCH(C10,__DATA__!$C$41:$C$43,0)),"Select an option from the dropdown above") -> Wash 3-4 celery stalks thoroughly. Include the leaves - they contain more nutrients than the stalks. Cut into 3-4 inch pieces or leave whole. | E10: =IFERROR(INDEX(__DATA__!$E$41:$E$43,MATCH(C10,__DATA__!$C$41:$C$43,0)),"") -> Default best choice - most powerful for sodium flush and bloat reduction. | F10: Cucumber Spears | G10: Fennel Stalks
A12: STEP-BY-STEP INSTRUCTIONS - Follow these steps in order
A13: Steps marked with * reference your dropdown selections above - those cells update automatically when you change your selection.
A14: STEP 1 - Soak Almonds the Night Before
A15: Place 12-15 raw almonds in a glass and cover with purified water. Leave overnight at room temperature or in the refrigerator. Drain and rinse in the morning. Soaked almonds are softer, easier to digest, and more nutritious because soaking neutralizes phytic acid which otherwise blocks mineral absorption.
A16: STEP 2 - Drink 16 oz Water First
A17: Before eating your snack, drink your full 16 oz of purified water. This is strategic - water first expands the stomach slightly so the small amount of food that follows registers as more filling than it would on an empty stomach.
A18: STEP 3 - Prepare and Eat Slowly
A19: See YOUR SELECTION column for your chosen snack option instructions. Eat slowly and deliberately over 10-15 minutes. Chew each almond at least 20 times. Sip your tea or juice throughout. The slower you eat, the more satisfied you will feel.
A21: TIPS AND NOTES
A22: - Still hungry after the snack? More crunchy vegetable is essentially unlimited. Try water and herbal tea before reaching for extra almonds.
A23: - 12-15 almonds is the right amount. Enough to stabilize blood sugar without overloading fat intake for the day.
A24: - Save celery leaves for the evening vegetable broth - adds flavor and nutrients, nothing wasted.
A25: - Juicer feels like too much effort in the afternoon? Replace juice with a second cup of herbal tea and an extra celery stalk.

Sheet Dinner
A1: 7-Day Organic Vegan Detox & Cleanse - Dinner
A2: Recipe: Dinner - Choose One of 3 Recipes | Time: 15-20 minutes | Method: Steamed, Sauteed, or Raw
A4: WHY THIS MEAL
A5: Dinner completes the day's toxin-binding cycle. The dark leafy green grabs toxins mobilized throughout the day and carries them out overnight. The starchy vegetable provides complex carbs that sustain blood sugar through the night and prevent the late hunger that causes people to break the cleanse. Not hungry? Warm vegetable broth is a fully acceptable substitute.
A7: INGREDIENT SLOTS - Use dropdowns in the YOUR SELECTION column to customize your recipe
B8: Ingredient Slot | C8: YOUR SELECTION | D8: Recipe Instructions (updates with your selection) | E8: Swap Note | F8: Alt Option 1 | G8: Alt Option 2
B9: Dinner Recipe | C9: Steamed Kale and Butternut Squash Bowl | D9: =IFERROR(INDEX(__DATA__!$D$44:$D$46,MATCH(C9,__DATA__!$C$44:$C$46,0)),"Select an option from the dropdown above") -> STEAMED KALE AND BUTTERNUT SQUASH BOWL: Peel and cube 1.5 cups butternut squash into 3/4-inch pieces. Cut your cruciferous vegetable into medium florets. Remove stems from your dark leafy green. Mince 2 garlic cloves and let rest 5 minutes. STEAM: 1.5 inches purified water, rolling boil. Add squash first (8-10 min total). After 4 min, add cruciferous. After 3 more min, add greens on top (2-3 min only). Test squash with fork - slight resistance is perfect. DRESSING: while steaming, combine 1 Tbsp olive oil, lemon juice, minced garlic, cayenne, and sodium-free seasoning in serving bowl. Add hot vegetables, toss immediately. Rest 2 minutes before eating. | E9: =IFERROR(INDEX(__DATA__!$E$44:$E$46,MATCH(C9,__DATA__!$C$44:$C$46,0)),"") -> Default dinner. Best for all 7 days. Batch-prep squash at week start. | F9: Sauteed Collards and Broccoli with Garlic | G9: Raw Detox Plate
B10: Dark Leafy Green | C10: Kale | D10: =IFERROR(INDEX(__DATA__!$D$47:$D$50,MATCH(C10,__DATA__!$C$47:$C$50,0)),"Select an option from the dropdown above") -> Remove stems completely. Tear into large pieces for steaming or large pieces for sauteing. Most potent toxin-binding green for dinner. | E10: =IFERROR(INDEX(__DATA__!$E$47:$E$50,MATCH(C10,__DATA__!$C$47:$C$50,0)),"") -> Most potent. Best everyday choice for all 7 days. | F10: Collard Greens | G10: Chard
B11: Starchy Vegetable | C11: Butternut Squash | D11: =IFERROR(INDEX(__DATA__!$D$51:$D$53,MATCH(C11,__DATA__!$C$51:$C$53,0)),"Select an option from the dropdown above") -> Peel and cube into 3/4-inch pieces. Uniform size is critical for even cooking. Easiest to prep. Mildly sweet. Batch-prep at week start - keeps 5-6 days refrigerated. | E11: =IFERROR(INDEX(__DATA__!$E$51:$E$53,MATCH(C11,__DATA__!$C$51:$C$53,0)),"") -> Easiest to prep. Best everyday choice for most dinners. | F11: Kabocha Squash | G11: Beets (cubed)
A13: STEP-BY-STEP INSTRUCTIONS - Follow these steps in order
A14: Steps marked with * reference your dropdown selections above - those cells update automatically when you change your selection.
A15: STEP 1 - Prep All Vegetables
A16: Choose your dinner recipe and vegetable swaps using the dropdowns above. See the YOUR SELECTION column for your specific recipe instructions. Do your prep: cube starchy vegetables, remove greens stems, slice garlic and let rest 5 minutes.
A17: STEP 2 - Cook Using Your Chosen Method
A18: Follow the recipe instructions in the YOUR SELECTION column exactly. For steamed dishes, never steam past slight fork resistance - slightly underdone is always better. For sauteed dishes, never overcrowd the pan - cook in batches if needed.
A19: STEP 3 - Dress and Serve
A20: Apply your dressing while vegetables are still hot so it absorbs into the food rather than sitting on the surface. The acid (lemon or lime) must always be applied OFF HEAT to preserve vitamin C. Rest 2 minutes then eat slowly. Not hungry? A cup of warm vegetable broth is a fully acceptable dinner substitute.
A22: TIPS AND NOTES
A23: - Days 5-7: double the dark leafy green at dinner. The fiber load at night is when the body does its most active elimination work.
A24: - Batch-prep butternut squash at week start - cube the entire squash, store in glass container, use across multiple dinners.
A25: - The steaming water left in the pot is nutritious broth - season lightly and drink warm after dinner.
A26: - Want more substance? Steam 1/2 cup extra squash separately and add to the sauteed recipe for the final 2 minutes.

Sheet Evening
A1: 7-Day Organic Vegan Detox & Cleanse - Evening
A2: Recipe: Evening Routine - Do NOT Skip This | Time: 5 min active + 10-15 min for tea | Method: Drinks
A4: WHY THIS MEAL
A5: Everything today mobilized toxins from fat cells, liver, lymphatic system, and gut wall into the digestive tract for elimination. This drink carries those toxins OUT of the body overnight. Without it, mobilized toxins can be reabsorbed through the intestinal wall - called autointoxication. This is the closing mechanism of the entire day's cleansing work. It is not optional.
A7: INGREDIENT SLOTS - Use dropdowns in the YOUR SELECTION column to customize your recipe
B8: Ingredient Slot | C8: YOUR SELECTION | D8: Recipe Instructions (updates with your selection) | E8: Swap Note | F8: Alt Option 1 | G8: Alt Option 2
B9: Evening Tea | C9: Detoxifying Herbal Tea | D9: =IFERROR(INDEX(__DATA__!$D$54:$D$57,MATCH(C9,__DATA__!$C$54:$C$57,0)),"Select an option from the dropdown above") -> DETOXIFYING HERBAL TEA: Bring purified water to near boil. Remove from heat and wait 60 seconds. Add 1-2 detox herbal tea bags. Steep 5-7 minutes COVERED - roots and barks need extended steeping to release active compounds. Remove bags WITHOUT squeezing - squeezing releases bitter tannins. Sit somewhere comfortable. No screens if possible. Drink slowly over 10-15 minutes. This is your signal that the day's cleansing work is done. | E9: =IFERROR(INDEX(__DATA__!$E$54:$E$57,MATCH(C9,__DATA__!$C$54:$C$57,0)),"") -> Best everyday option. Look for dandelion root, burdock, or milk thistle on the label. | F9: Chamomile Tea | G9: Dandelion Root Tea
A11: STEP-BY-STEP INSTRUCTIONS - Follow these steps in order
A12: Steps marked with * reference your dropdown selections above - those cells update automatically when you change your selection.
A13: STEP 1 - Time This Correctly - Read Before Starting
A14: The evening fiber drink must be consumed at least 90 minutes after dinner and at least 30 minutes before bed. Too close to dinner: competes with digestion. Too close to sleep: the bulk creates discomfort. Ideal: approximately 8-9 PM for people who sleep around 10:30-11 PM.
A15: STEP 2 - Prepare and DRINK FAST - Read Fully Before Starting
A16: STEP A: Add 8-10 oz ROOM TEMPERATURE purified water to shaker bottle first. STEP B: Add 1 Tbsp ground flax seed. Add 1 Tbsp psyllium husk. Do NOT add cranberry - morning only. STEP C: Seal immediately. Do not wait. STEP D: Shake vigorously 10-15 seconds. STEP E - CRITICAL: Open and drink the ENTIRE contents IMMEDIATELY and CONTINUOUSLY. Do NOT sip slowly. Psyllium husk begins gelling within 60-90 seconds. The ENTIRE drink must be consumed within 30-45 seconds of opening. DRINK IT FAST, ALL AT ONCE.
A17: STEP 3 - Follow Immediately with 8 oz Water - No Pause
A18: Without pausing, drink an additional 8 oz of purified water immediately after the fiber drink. This second glass is NOT optional. Psyllium husk requires significant water - insufficient water can cause the fiber to swell in the esophagus rather than the intestines. The water physically pushes the fiber mixture down where it belongs.
A19: STEP 4 - Brew and Drink Your Evening Tea
A20: See YOUR SELECTION column for your chosen tea instructions. Sit somewhere comfortable. Drink slowly over 10-15 minutes. No screens if possible. This is the signal to your body that the day's work is done. The body does its most active overnight cleansing when the nervous system shifts to a relaxed state.
A22: TIPS AND NOTES
A23: - MOST IMPORTANT TIP: Drink the fiber drink FAST - all at once - then chase IMMEDIATELY with 8 oz water. Do not sip it slowly.
... A26: - Whole flax seeds are NOT a substitute for ground flax seed - the body cannot digest whole flax. Must be pre-ground.

Sheet Shopping List
A1: 7-Day Organic Vegan Detox & Cleanse - Shopping List
A2: Tick checkboxes in column A as you shop. For Pick One categories, check only one option.
A4: Budget guide: One-time equipment varies based on what you already own. Per-cleanse groceries ~$80-120 per week. Supplements restock as needed across multiple cleanses.
A6: SECTION 1 - ONE-TIME EQUIPMENT
A7: Buy once, use every cleanse. Each pick-one category requires only ONE item - choose the option that fits your needs and budget.
B8: Item / Category | C8: Options / Notes | D8: Details | E8: Type
B9: Blender - Required for smoothies and green drinks | E9: Pick One
B10: Ninja Professional | C10: Best value for daily smoothie use. Buy once, lasts years. | E10: Option
B11: Vitamix (Premium) | C11: Lifetime investment. The last blender you will ever buy. | E11: Option
B13: Juicer - Required for mid-morning and afternoon juices | E13: Pick One
B14: Omega Masticating | C14: Best nutrient retention. Highly recommended over centrifugal. | E14: Option
B15: Breville Centrifugal | C15: Faster and easier to clean. Good beginner option. | E15: Option
B17: Steamer - Required for dinner vegetable preparation | E17: Pick One
B18: Tiered Electric Steamer | C18: Multi-stage cooking - squash, broccoli, and greens simultaneously. | E18: Option
B19: Stainless Basket (stovetop) | C19: Fits inside any pot. Simple, inexpensive, effective. | E19: Option
B20: Bamboo Steamer (2-tier) | C20: Traditional steaming. No electricity needed. 2-tier 10-inch. | E20: Option
B22: Portable Cooler - Optional - for taking meals away from home | E22: Pick One
B23: Lunch Cooler | C23: Keeps salads, juices, and snacks fresh. Best for half-day outings. | E23: Option
B24: Large Soft-Sided Cooler | C24: Fits a full day of meals with ice packs. Best for full-day outings. | E24: Option
B25: Electric DC/Wall Cooler | C25: Operates on car or wall power. Best for frequent travelers. | E25: Option
B27: Smart Body Scale | C27: Weight, BMI, body fat %, muscle %, water %, bone %. Connects to phone. | E27: Equipment
B28: Shaker Bottle (16 oz+ with ball) | C28: Essential for morning and evening fiber drinks. The blender ball prevents clumping. | E28: Equipment
B29: Glass Water Bottle (32 oz+) | C29: For tracking daily water intake. Fill it twice daily to hit your gallon goal. | E29: Equipment
B30: Glass Food Storage Containers | C30: Pyrex set - for meal prep, soaking almonds and prunes, batch-prepped squash. | E30: Equipment
B31: Stainless Steel Skillet (12-inch) | C31: Wide pan essential for sauteed dinner recipes. Prevents overcrowding. | E31: Equipment
B32: Box Grater (stainless steel) | C32: For grating raw beets and carrots. You use this every cleanse. | E32: Equipment
B33: Portable Kitchen Scale (digital) | C33: For precise ingredient portions. Compact enough to pack for travel. | E33: Equipment
B34: Portable Mini Photo Printer | C34: Canon Ivy, HP Sprocket, or Polaroid Hi-Print. Prints progress photos from phone. | E34: Equipment
A36: SECTION 2 - PER-CLEANSE GROCERIES
A37: Buy fresh each time. Two shopping trips recommended: once before Day 1, and once around Day 4 for peak freshness.
A38: Delivery option: Amazon Fresh, Whole Foods, Instacart, Sam's Club, or Costco can deliver most of this list. See the companion app Shop tab for direct links.
B39: Item / Category | C39: Options / Notes | D39: Details | E39: Type
A40: Pre-Cleanse Meal
B41: Wild-Caught Salmon (1-2 lbs) | C41: Pre-cleanse meal only. Wild-caught preferred over farmed for lower toxin load. | E41: Pre-Cleanse
B42: Fresh Asparagus (1 bunch) | C42: Pre-cleanse meal. Natural diuretic - begins the cleansing process. | E42: Pre-Cleanse
B43: Organic Black Rice | C43: Pre-cleanse meal only. Also called forbidden rice. | E43: Pre-Cleanse
A45: Fresh Produce
B46: Organic Apples (12-24 count bag) | C46: Used daily in juices, smoothies, salads, snacks. Buy in bulk. | E46: Produce
B47: Organic Kale (2-3 large bunches) | C47: Most important green in the program. Restock around Day 4. | E47: Produce
B48: Organic Spinach (large bag) | C48: Best beginner green for smoothies and salads. | E48: Produce
...

Sheet Weekly Tracker
A1: 7-Day Organic Vegan Detox & Cleanse - Weekly Progress Tracker
A2: Enter measurements each morning before eating or drinking. Yellow cells = your input. Green = auto-calculated.
A4: BODY METRICS - Weigh yourself each morning before eating or drinking
B5: Metric | C5: Day 1 | D5: Day 2 | E5: Day 3 | F5: Day 4 | G5: Day 5 | H5: Day 6 | I5: Day 7 | J5: Total Change | K5: Notes
B6: Weight (lbs) | J6: =IFERROR(IF(AND(I6<>"",C6<>""),I6-C6,""),"--")
B7: BMI | J7: =IFERROR(IF(AND(I7<>"",C7<>""),I7-C7,""),"--")
B8: Body Fat % | J8: =IFERROR(IF(AND(I8<>"",C8<>""),I8-C8,""),"--")
B9: Muscle % | J9: =IFERROR(IF(AND(I9<>"",C9<>""),I9-C9,""),"--")
B10: Bone % | J10: =IFERROR(IF(AND(I10<>"",C10<>""),I10-C10,""),"--")
B11: Water % | J11: =IFERROR(IF(AND(I11<>"",C11<>""),I11-C11,""),"--")
B12: Waist (inches) | J12: =IFERROR(IF(AND(I12<>"",C12<>""),I12-C12,""),"--")
A14: DAILY WATER TRACKER - Goal: 1 Gallon Per Day (8+ large glasses)
C15: Day 1 | D15: Day 2 | E15: Day 3 | F15: Day 4 | G15: Day 5 | H15: Day 6 | I15: Day 7 | J15: Daily Average
B16: Glasses consumed | J16: =IFERROR(ROUND(AVERAGE(C16:I16),1),"--") -> --
A18: DAILY WELLNESS CHECK - Rate each 1-10 (1=worst, 10=best)
B19: How are you feeling? | C19: Day 1 | D19: Day 2 | E19: Day 3 | F19: Day 4 | G19: Day 5 | H19: Day 6 | I19: Day 7 | J19: Trend
B20: Energy Level | J20: =IFERROR(IF(I20="","",IF(I20>C20,"Up - Improving",IF(I20<C20,"Down - Declining","Same"))),"--")
B21: Mental Clarity | J21: =IFERROR(IF(I21="","",IF(I21>C21,"Up - Improving",IF(I21<C21,"Down - Declining","Same"))),"--")
B22: Mood | J22: =IFERROR(IF(I22="","",IF(I22>C22,"Up - Improving",IF(I22<C22,"Down - Declining","Same"))),"--")
B23: Sleep Quality | J23: =IFERROR(IF(I23="","",IF(I23>C23,"Up - Improving",IF(I23<C23,"Down - Declining","Same"))),"--")
B24: Hunger (10=not hungry) | J24: =IFERROR(IF(I24="","",IF(I24>C24,"Up - Improving",IF(I24<C24,"Down - Declining","Same"))),"--")
B25: Skin Appearance | J25: =IFERROR(IF(I25="","",IF(I25>C25,"Up - Improving",IF(I25<C25,"Down - Declining","Same"))),"--")
B26: Digestion | J26: =IFERROR(IF(I26="","",IF(I26>C26,"Up - Improving",IF(I26<C26,"Down - Declining","Same"))),"--")
B27: Overall Feeling | J27: =IFERROR(IF(I27="","",IF(I27>C27,"Up - Improving",IF(I27<C27,"Down - Declining","Same"))),"--")
A29: DAILY JOURNAL - One brief reflection per prompt each evening
B30: Journal Prompt | C30: Day 1 | D30: Day 2 | E30: Day 3 | F30: Day 4 | G30: Day 5 | H30: Day 6 | I30: Day 7
B31: What was hardest today?
B32: What surprised you?
B33: What did you notice about your body?
B34: What did you eat or drink that you loved?
B35: What will you do differently tomorrow?
B36: Commitment rating today (1-10)
A38: END OF WEEK RESULTS
A39: Result | F39: Your Answer
A40: Total weight lost (lbs)
A41: Energy improvement - Day 7 compared to Day 1
A42: Skin improvement noticed?
A43: Brain fog cleared?
A44: Digestion improvement noticed?
A45: Would you do this again?
...
